Workbook

Sheet Raw_La_Liga data
A1: Temporada | B1: Jornada | C1: Fecha | D1: Hora | E1: Equipo Local | F1: Equipo Visitante | G1: Resultado | H1: Arbitro
A2: 2013-14 | B2: 1 | C2: SAB 17.08.2013 | D2: 0.79166667 | E2: Real Sociedad | F2: Getafe CF | G2: 2-0 | H2: -
A3: 2013-14 | B3: 1 | C3: SAB 17.08.2013 | D3: 0.875 | E3: Real Valladolid CF | F3: Athletic Club | G3: 46054 | H3: -
A4: 2013-14 | B4: 1 | C4: SAB 17.08.2013 | D4: 0.95833333 | E4: Valencia CF | F4: MÃ¡laga CF | G4: 1-0 | H4: -
A5: 2013-14 | B5: 1 | C5: DOM 18.08.2013 | D5: 0.79166667 | E5: FC Barcelona | F5: Levante UD | G5: 7-0 | H5: -
A6: 2013-14 | B6: 1 | C6: DOM 18.08.2013 | D6: 0.875 | E6: CA Osasuna | F6: Granada CF | G6: 46054 | H6: -
A7: 2013-14 | B7: 1 | C7: DOM 18.08.2013 | D7: 0.875 | E7: Real Madrid | F7: Real Betis | G7: 46024 | H7: -
A8: 2013-14 | B8: 1 | C8: DOM 18.08.2013 | D8: 0.95833333 | E8: Sevilla FC | F8: AtlÃ©tico de Madrid | G8: 46082 | H8: -
A9: 2013-14 | B9: 1 | C9: LUN 19.08.2013 | D9: 0.83333333 | E9: Rayo Vallecano | F9: Elche CF | G9: 3-0 | H9: -
A10: 2013-14 | B10: 1 | C10: LUN 19.08.2013 | D10: 0.91666667 | E10: UD AlmerÃ­a | F10: Villarreal CF | G10: 46083 | H10: -
A11: 2013-14 | B11: 1 | C11: LUN 19.08.2013 | D11: 0.91666667 | E11: RC Celta | F11: RCD Espanyol de Barcelona | G11: 46055 | H11: -
A12: 2013-14 | B12: 2 | C12: VIE 23.08.2013 | D12: 0.83333333 | E12: Getafe CF | F12: UD AlmerÃ­a | G12: 46055 | H12: -
A13: 2013-14 | B13: 2 | C13: VIE 23.08.2013 | D13: 0.91666667 | E13: Athletic Club | F13: CA Osasuna | G13: 2-0 | H13: -
A14: 2013-14 | B14: 2 | C14: SAB 24.08.2013 | D14: 0.79166667 | E14: Elche CF | F14: Real Sociedad | G14: 46023 | H14: -
A15: 2013-14 | B15: 2 | C15: SAB 24.08.2013 | D15: 0.875 | E15: RCD Espanyol de Barcelona | F15: Valencia CF | G15: 46025 | H15: -
A16: 2013-14 | B16: 2 | C16: SAB 24.08.2013 | D16: 0.95833333 | E16: Villarreal CF | F16: Real Valladolid CF | G16: 46024 | H16: -
A17: 2013-14 | B17: 2 | C17: DOM 25.08.2013 | D17: 0.79166667 | E17: AtlÃ©tico de Madrid | F17: Rayo Vallecano | G17: 5-0 | H17: -
A18: 2013-14 | B18: 2 | C18: DOM 25.08.2013 | D18: 0.875 | E18: Levante UD | F18: Sevilla FC | G18: 0-0 | H18: -
A19: 2013-14 | B19: 2 | C19: DOM 25.08.2013 | D19: 0.875 | E19: MÃ¡laga CF | F19: FC Barcelona | G19: 0-1 | H19: -
A20: 2013-14 | B20: 2 | C20: DOM 25.08.2013 | D20: 0.95833333 | E20: Real Betis | F20: RC Celta | G20: 46054 | H20: -
A21: 2013-14 | B21: 2 | C21: LUN 26.08.2013 | D21: 0.875 | E21: Granada CF | F21: Real Madrid | G21: 0-1 | H21: -
A22: 2013-14 | B22: 3 | C22: VIE 30.08.2013 | D22: 0.95833333 | E22: UD AlmerÃ­a | F22: Elche CF | G22: 46055 | H22: -
A23: 2013-14 | B23: 3 | C23: VIE 30.08.2013 | D23: 0.95833333 | E23: Rayo Vallecano | F23: Levante UD | G23: 46054 | H23: -
A24: 2013-14 | B24: 3 | C24: SAB 31.08.2013 | D24: 0.79166667 | E24: RC Celta | F24: Granada CF | G24: 46023 | H24: -
A25: 2013-14 | B25: 3 | C25: SAB 31.08.2013 | D25: 0.875 | E25: Real Valladolid CF | F25: Getafe CF | G25: 1-0 | H25: -
A26: 2013-14 | B26: 3 | C26: SAB 31.08.2013 | D26: 0.95833333 | E26: CA Osasuna | F26: Villarreal CF | G26: 0-3 | H26: -
A27: 2013-14 | B27: 3 | C27: DOM 01.09.2013 | D27: 0.5 | E27: Real Madrid | F27: Athletic Club | G27: 46025 | H27: -
A28: 2013-14 | B28: 3 | C28: DOM 01.09.2013 | D28: 0.70833333 | E28: RCD Espanyol de Barcelona | F28: Real Betis | G28: 0-0 | H28: -
A29: 2013-14 | B29: 3 | C29: DOM 01.09.2013 | D29: 0.79166667 | E29: Real Sociedad | F29: AtlÃ©tico de Madrid | G29: 46054 | H29: -
A30: 2013-14 | B30: 3 | C30: DOM 01.09.2013 | D30: 0.875 | E30: Sevilla FC | F30: MÃ¡laga CF | G30: 46055 | H30: -
A31: 2013-14 | B31: 3 | C31: DOM 01.09.2013 | D31: 0.875 | E31: Valencia CF | F31: FC Barcelona | G31: 46083 | H31: -
A32: 2013-14 | B32: 4 | C32: SAB 14.09.2013 | D32: 0.66666667 | E32: AtlÃ©tico de Madrid | F32: UD AlmerÃ­a | G32: 46057 | H32: -
A33: 2013-14 | B33: 4 | C33: SAB 14.09.2013 | D33: 0.75 | E33: Levante UD | F33: Real Sociedad | G33: 0-0 | H33: -
A34: 2013-14 | B34: 4 | C34: SAB 14.09.2013 | D34: 0.83333333 | E34: FC Barcelona | F34: Sevilla FC | G34: 46056 | H34: -
A35: 2013-14 | B35: 4 | C35: SAB 14.09.2013 | D35: 0.91666667 | E35: Villarreal CF | F35: Real Madrid | G35: 46055 | H35: -
A36: 2013-14 | B36: 4 | C36: DOM 15.09.2013 | D36: 0.5 | E36: Granada CF | F36: RCD Espanyol de Barcelona | G36: 0-1 | H36: -
A37: 2013-14 | B37: 4 | C37: DOM 15.09.2013 | D37: 0.70833333 | E37: Getafe CF | F37: CA Osasuna | G37: 46024 | H37: -
A38: 2013-14 | B38: 4 | C38: DOM 15.09.2013 | D38: 0.79166667 | E38: MÃ¡laga CF | F38: Rayo Vallecano | G38: 5-0 | H38: -
A39: 2013-14 | B39: 4 | C39: DOM 15.09.2013 | D39: 0.875 | E39: Real Betis | F39: Valencia CF | G39: 46025 | H39: -
A40: 2013-14 | B40: 4 | C40: LUN 16.09.2013 | D40: 0.83333333 | E40: Elche CF | F40: Real Valladolid CF | G40: 0-0 | H40: -
...

Sheet Cleaned_Liga_Data
A1: Season | B1: Match_Day | C1: Match_Date | D1: Match_Date_Clean | E1: Match_Time | F1: Home_Team | G1: Away_team | H1: Resultado | I1: Final_Score_Clean | J1: Home_Team_Goal | K1: Away_Team_Goal | L1: Winner | M1: Leauge Winner
A2: 2013-14 | B2: 1 | C2: SAB 17.08.2013 | D2: =RIGHT(C2,10) -> 17.08.2013 | E2: 0.79166667 | F2: Real Sociedad | G2: Getafe CF | H2: 2-0 | I2: =IF(ISNUMBER(SEARCH("-",H2)),H2,"") -> 2-0 | J2: =IF(I2="","",LEFT(I2,FIND("-",I2)-1)) -> 2 | K2: =IF(I2="","",RIGHT(I2,LEN(I2)-FIND("-",I2))) -> 0 | L2: =IF(I2="","",IF(J2>K2,F2,IF(K2>J2,G2,"Draw"))) -> Real Sociedad | M2: =IF(COUNTIF($A$2:A2,A2)=1, VLOOKUP(A2,Season_Winners!A:B,2,FALSE), "") -> Atlético de Madrid
A3: 2013-14 | B3: 1 | C3: SAB 17.08.2013 | D3: =RIGHT(C3,10) -> 17.08.2013 | E3: 0.875 | F3: Real Valladolid CF | G3: Athletic Club | H3: 46054 | I3: =IF(ISNUMBER(SEARCH("-",H3)),H3,"") | J3: =IF(I3="","",LEFT(I3,FIND("-",I3)-1)) | K3: =IF(I3="","",RIGHT(I3,LEN(I3)-FIND("-",I3))) | L3: =IF(I3="","",IF(J3>K3,F3,IF(K3>J3,G3,"Draw"))) | M3: =IF(COUNTIF($A$2:A3,A3)=1, VLOOKUP(A3,Season_Winners!A:B,2,FALSE), "")
A4: 2013-14 | B4: 1 | C4: SAB 17.08.2013 | D4: =RIGHT(C4,10) -> 17.08.2013 | E4: 0.95833333 | F4: Valencia CF | G4: MÃ¡laga CF | H4: 1-0 | I4: =IF(ISNUMBER(SEARCH("-",H4)),H4,"") -> 1-0 | J4: =IF(I4="","",LEFT(I4,FIND("-",I4)-1)) -> 1 | K4: =IF(I4="","",RIGHT(I4,LEN(I4)-FIND("-",I4))) -> 0 | L4: =IF(I4="","",IF(J4>K4,F4,IF(K4>J4,G4,"Draw"))) -> Valencia CF | M4: =IF(COUNTIF($A$2:A4,A4)=1, VLOOKUP(A4,Season_Winners!A:B,2,FALSE), "")
A5: 2013-14 | B5: 1 | C5: DOM 18.08.2013 | D5: =RIGHT(C5,10) -> 18.08.2013 | E5: 0.79166667 | F5: FC Barcelona | G5: Levante UD | H5: 7-0 | I5: =IF(ISNUMBER(SEARCH("-",H5)),H5,"") -> 7-0 | J5: =IF(I5="","",LEFT(I5,FIND("-",I5)-1)) -> 7 | K5: =IF(I5="","",RIGHT(I5,LEN(I5)-FIND("-",I5))) -> 0 | L5: =IF(I5="","",IF(J5>K5,F5,IF(K5>J5,G5,"Draw"))) -> FC Barcelona | M5: =IF(COUNTIF($A$2:A5,A5)=1, VLOOKUP(A5,Season_Winners!A:B,2,FALSE), "")
A6: 2013-14 | B6: 1 | C6: DOM 18.08.2013 | D6: =RIGHT(C6,10) -> 18.08.2013 | E6: 0.875 | F6: CA Osasuna | G6: Granada CF | H6: 46054 | I6: =IF(ISNUMBER(SEARCH("-",H6)),H6,"") | J6: =IF(I6="","",LEFT(I6,FIND("-",I6)-1)) | K6: =IF(I6="","",RIGHT(I6,LEN(I6)-FIND("-",I6))) | L6: =IF(I6="","",IF(J6>K6,F6,IF(K6>J6,G6,"Draw"))) | M6: =IF(COUNTIF($A$2:A6,A6)=1, VLOOKUP(A6,Season_Winners!A:B,2,FALSE), "")
A7: 2013-14 | B7: 1 | C7: DOM 18.08.2013 | D7: =RIGHT(C7,10) -> 18.08.2013 | E7: 0.875 | F7: Real Madrid | G7: Real Betis | H7: 46024 | I7: =IF(ISNUMBER(SEARCH("-",H7)),H7,"") | J7: =IF(I7="","",LEFT(I7,FIND("-",I7)-1)) | K7: =IF(I7="","",RIGHT(I7,LEN(I7)-FIND("-",I7))) | L7: =IF(I7="","",IF(J7>K7,F7,IF(K7>J7,G7,"Draw"))) | M7: =IF(COUNTIF($A$2:A7,A7)=1, VLOOKUP(A7,Season_Winners!A:B,2,FALSE), "")
A8: 2013-14 | B8: 1 | C8: DOM 18.08.2013 | D8: =RIGHT(C8,10) -> 18.08.2013 | E8: 0.95833333 | F8: Sevilla FC | G8: AtlÃ©tico de Madrid | H8: 46082 | I8: =IF(ISNUMBER(SEARCH("-",H8)),H8,"") | J8: =IF(I8="","",LEFT(I8,FIND("-",I8)-1)) | K8: =IF(I8="","",RIGHT(I8,LEN(I8)-FIND("-",I8))) | L8: =IF(I8="","",IF(J8>K8,F8,IF(K8>J8,G8,"Draw"))) | M8: =IF(COUNTIF($A$2:A8,A8)=1, VLOOKUP(A8,Season_Winners!A:B,2,FALSE), "")
A9: 2013-14 | B9: 1 | C9: LUN 19.08.2013 | D9: =RIGHT(C9,10) -> 19.08.2013 | E9: 0.83333333 | F9: Rayo Vallecano | G9: Elche CF | H9: 3-0 | I9: =IF(ISNUMBER(SEARCH("-",H9)),H9,"") -> 3-0 | J9: =IF(I9="","",LEFT(I9,FIND("-",I9)-1)) -> 3 | K9: =IF(I9="","",RIGHT(I9,LEN(I9)-FIND("-",I9))) -> 0 | L9: =IF(I9="","",IF(J9>K9,F9,IF(K9>J9,G9,"Draw"))) -> Rayo Vallecano | M9: =IF(COUNTIF($A$2:A9,A9)=1, VLOOKUP(A9,Season_Winners!A:B,2,FALSE), "")
A10: 2013-14 | B10: 1 | C10: LUN 19.08.2013 | D10: =RIGHT(C10,10) -> 19.08.2013 | E10: 0.91666667 | F10: UD AlmerÃ­a | G10: Villarreal CF | H10: 46083 | I10: =IF(ISNUMBER(SEARCH("-",H10)),H10,"") | J10: =IF(I10="","",LEFT(I10,FIND("-",I10)-1)) | K10: =IF(I10="","",RIGHT(I10,LEN(I10)-FIND("-",I10))) | L10: =IF(I10="","",IF(J10>K10,F10,IF(K10>J10,G10,"Draw"))) | M10: =IF(COUNTIF($A$2:A10,A10)=1, VLOOKUP(A10,Season_Winners!A:B,2,FALSE), "")
A11: 2013-14 | B11: 1 | C11: LUN 19.08.2013 | D11: =RIGHT(C11,10) -> 19.08.2013 | E11: 0.91666667 | F11: RC Celta | G11: RCD Espanyol de Barcelona | H11: 46055 | I11: =IF(ISNUMBER(SEARCH("-",H11)),H11,"") | J11: =IF(I11="","",LEFT(I11,FIND("-",I11)-1)) | K11: =IF(I11="","",RIGHT(I11,LEN(I11)-FIND("-",I11))) | L11: =IF(I11="","",IF(J11>K11,F11,IF(K11>J11,G11,"Draw"))) | M11: =IF(COUNTIF($A$2:A11,A11)=1, VLOOKUP(A11,Season_Winners!A:B,2,FALSE), "")
A12: 2013-14 | B12: 2 | C12: VIE 23.08.2013 | D12: =RIGHT(C12,10) -> 23.08.2013 | E12: 0.83333333 | F12: Getafe CF | G12: UD AlmerÃ­a | H12: 46055 | I12: =IF(ISNUMBER(SEARCH("-",H12)),H12,"") | J12: =IF(I12="","",LEFT(I12,FIND("-",I12)-1)) | K12: =IF(I12="","",RIGHT(I12,LEN(I12)-FIND("-",I12))) | L12: =IF(I12="","",IF(J12>K12,F12,IF(K12>J12,G12,"Draw"))) | M12: =IF(COUNTIF($A$2:A12,A12)=1, VLOOKUP(A12,Season_Winners!A:B,2,FALSE), "")
A13: 2013-14 | B13: 2 | C13: VIE 23.08.2013 | D13: =RIGHT(C13,10) -> 23.08.2013 | E13: 0.91666667 | F13: Athletic Club | G13: CA Osasuna | H13: 2-0 | I13: =IF(ISNUMBER(SEARCH("-",H13)),H13,"") -> 2-0 | J13: =IF(I13="","",LEFT(I13,FIND("-",I13)-1)) -> 2 | K13: =IF(I13="","",RIGHT(I13,LEN(I13)-FIND("-",I13))) -> 0 | L13: =IF(I13="","",IF(J13>K13,F13,IF(K13>J13,G13,"Draw"))) -> Athletic Club | M13: =IF(COUNTIF($A$2:A13,A13)=1, VLOOKUP(A13,Season_Winners!A:B,2,FALSE), "")
A14: 2013-14 | B14: 2 | C14: SAB 24.08.2013 | D14: =RIGHT(C14,10) -> 24.08.2013 | E14: 0.79166667 | F14: Elche CF | G14: Real Sociedad | H14: 46023 | I14: =IF(ISNUMBER(SEARCH("-",H14)),H14,"") | J14: =IF(I14="","",LEFT(I14,FIND("-",I14)-1)) | K14: =IF(I14="","",RIGHT(I14,LEN(I14)-FIND("-",I14))) | L14: =IF(I14="","",IF(J14>K14,F14,IF(K14>J14,G14,"Draw"))) | M14: =IF(COUNTIF($A$2:A14,A14)=1, VLOOKUP(A14,Season_Winners!A:B,2,FALSE), "")
A15: 2013-14 | B15: 2 | C15: SAB 24.08.2013 | D15: =RIGHT(C15,10) -> 24.08.2013 | E15: 0.875 | F15: RCD Espanyol de Barcelona | G15: Valencia CF | H15: 46025 | I15: =IF(ISNUMBER(SEARCH("-",H15)),H15,"") | J15: =IF(I15="","",LEFT(I15,FIND("-",I15)-1)) | K15: =IF(I15="","",RIGHT(I15,LEN(I15)-FIND("-",I15))) | L15: =IF(I15="","",IF(J15>K15,F15,IF(K15>J15,G15,"Draw"))) | M15: =IF(COUNTIF($A$2:A15,A15)=1, VLOOKUP(A15,Season_Winners!A:B,2,FALSE), "")
A16: 2013-14 | B16: 2 | C16: SAB 24.08.2013 | D16: =RIGHT(C16,10) -> 24.08.2013 | E16: 0.95833333 | F16: Villarreal CF | G16: Real Valladolid CF | H16: 46024 | I16: =IF(ISNUMBER(SEARCH("-",H16)),H16,"") | J16: =IF(I16="","",LEFT(I16,FIND("-",I16)-1)) | K16: =IF(I16="","",RIGHT(I16,LEN(I16)-FIND("-",I16))) | L16: =IF(I16="","",IF(J16>K16,F16,IF(K16>J16,G16,"Draw"))) | M16: =IF(COUNTIF($A$2:A16,A16)=1, VLOOKUP(A16,Season_Winners!A:B,2,FALSE), "")
A17: 2013-14 | B17: 2 | C17: DOM 25.08.2013 | D17: =RIGHT(C17,10) -> 25.08.2013 | E17: 0.79166667 | F17: Atlético de Madrid | G17: Rayo Vallecano | H17: 5-0 | I17: =IF(ISNUMBER(SEARCH("-",H17)),H17,"") -> 5-0 | J17: =IF(I17="","",LEFT(I17,FIND("-",I17)-1)) -> 5 | K17: =IF(I17="","",RIGHT(I17,LEN(I17)-FIND("-",I17))) -> 0 | L17: =IF(I17="","",IF(J17>K17,F17,IF(K17>J17,G17,"Draw"))) -> Atlético de Madrid | M17: =IF(COUNTIF($A$2:A17,A17)=1, VLOOKUP(A17,Season_Winners!A:B,2,FALSE), "")
A18: 2013-14 | B18: 2 | C18: DOM 25.08.2013 | D18: =RIGHT(C18,10) -> 25.08.2013 | E18: 0.875 | F18: Levante UD | G18: Sevilla FC | H18: 0-0 | I18: =IF(ISNUMBER(SEARCH("-",H18)),H18,"") -> 0-0 | J18: =IF(I18="","",LEFT(I18,FIND("-",I18)-1)) -> 0 | K18: =IF(I18="","",RIGHT(I18,LEN(I18)-FIND("-",I18))) -> 0 | L18: =IF(I18="","",IF(J18>K18,F18,IF(K18>J18,G18,"Draw"))) -> Draw | M18: =IF(COUNTIF($A$2:A18,A18)=1, VLOOKUP(A18,Season_Winners!A:B,2,FALSE), "")
A19: 2013-14 | B19: 2 | C19: DOM 25.08.2013 | D19: =RIGHT(C19,10) -> 25.08.2013 | E19: 0.875 | F19: MÃ¡laga CF | G19: FC Barcelona | H19: 0-1 | I19: =IF(ISNUMBER(SEARCH("-",H19)),H19,"") -> 0-1 | J19: =IF(I19="","",LEFT(I19,FIND("-",I19)-1)) -> 0 | K19: =IF(I19="","",RIGHT(I19,LEN(I19)-FIND("-",I19))) -> 1 | L19: =IF(I19="","",IF(J19>K19,F19,IF(K19>J19,G19,"Draw"))) -> FC Barcelona | M19: =IF(COUNTIF($A$2:A19,A19)=1, VLOOKUP(A19,Season_Winners!A:B,2,FALSE), "")
A20: 2013-14 | B20: 2 | C20: DOM 25.08.2013 | D20: =RIGHT(C20,10) -> 25.08.2013 | E20: 0.95833333 | F20: Real Betis | G20: RC Celta | H20: 46054 | I20: =IF(ISNUMBER(SEARCH("-",H20)),H20,"") | J20: =IF(I20="","",LEFT(I20,FIND("-",I20)-1)) | K20: =IF(I20="","",RIGHT(I20,LEN(I20)-FIND("-",I20))) | L20: =IF(I20="","",IF(J20>K20,F20,IF(K20>J20,G20,"Draw"))) | M20: =IF(COUNTIF($A$2:A20,A20)=1, VLOOKUP(A20,Season_Winners!A:B,2,FALSE), "")
A21: 2013-14 | B21: 2 | C21: LUN 26.08.2013 | D21: =RIGHT(C21,10) -> 26.08.2013 | E21: 0.875 | F21: Granada CF | G21: Real Madrid | H21: 0-1 | I21: =IF(ISNUMBER(SEARCH("-",H21)),H21,"") -> 0-1 | J21: =IF(I21="","",LEFT(I21,FIND("-",I21)-1)) -> 0 | K21: =IF(I21="","",RIGHT(I21,LEN(I21)-FIND("-",I21))) -> 1 | L21: =IF(I21="","",IF(J21>K21,F21,IF(K21>J21,G21,"Draw"))) -> Real Madrid | M21: =IF(COUNTIF($A$2:A21,A21)=1, VLOOKUP(A21,Season_Winners!A:B,2,FALSE), "")
A22: 2013-14 | B22: 3 | C22: VIE 30.08.2013 | D22: =RIGHT(C22,10) -> 30.08.2013 | E22: 0.95833333 | F22: UD AlmerÃ­a | G22: Elche CF | H22: 46055 | I22: =IF(ISNUMBER(SEARCH("-",H22)),H22,"") | J22: =IF(I22="","",LEFT(I22,FIND("-",I22)-1)) | K22: =IF(I22="","",RIGHT(I22,LEN(I22)-FIND("-",I22))) | L22: =IF(I22="","",IF(J22>K22,F22,IF(K22>J22,G22,"Draw"))) | M22: =IF(COUNTIF($A$2:A22,A22)=1, VLOOKUP(A22,Season_Winners!A:B,2,FALSE), "")
A23: 2013-14 | B23: 3 | C23: VIE 30.08.2013 | D23: =RIGHT(C23,10) -> 30.08.2013 | E23: 0.95833333 | F23: Rayo Vallecano | G23: Levante UD | H23: 46054 | I23: =IF(ISNUMBER(SEARCH("-",H23)),H23,"") | J23: =IF(I23="","",LEFT(I23,FIND("-",I23)-1)) | K23: =IF(I23="","",RIGHT(I23,LEN(I23)-FIND("-",I23))) | L23: =IF(I23="","",IF(J23>K23,F23,IF(K23>J23,G23,"Draw"))) | M23: =IF(COUNTIF($A$2:A23,A23)=1, VLOOKUP(A23,Season_Winners!A:B,2,FALSE), "")
A24: 2013-14 | B24: 3 | C24: SAB 31.08.2013 | D24: =RIGHT(C24,10) -> 31.08.2013 | E24: 0.79166667 | F24: RC Celta | G24: Granada CF | H24: 46023 | I24: =IF(ISNUMBER(SEARCH("-",H24)),H24,"") | J24: =IF(I24="","",LEFT(I24,FIND("-",I24)-1)) | K24: =IF(I24="","",RIGHT(I24,LEN(I24)-FIND("-",I24))) | L24: =IF(I24="","",IF(J24>K24,F24,IF(K24>J24,G24,"Draw"))) | M24: =IF(COUNTIF($A$2:A24,A24)=1, VLOOKUP(A24,Season_Winners!A:B,2,FALSE), "")
A25: 2013-14 | B25: 3 | C25: SAB 31.08.2013 | D25: =RIGHT(C25,10) -> 31.08.2013 | E25: 0.875 | F25: Real Valladolid CF | G25: Getafe CF | H25: 1-0 | I25: =IF(ISNUMBER(SEARCH("-",H25)),H25,"") -> 1-0 | J25: =IF(I25="","",LEFT(I25,FIND("-",I25)-1)) -> 1 | K25: =IF(I25="","",RIGHT(I25,LEN(I25)-FIND("-",I25))) -> 0 | L25: =IF(I25="","",IF(J25>K25,F25,IF(K25>J25,G25,"Draw"))) -> Real Valladolid CF | M25: =IF(COUNTIF($A$2:A25,A25)=1, VLOOKUP(A25,Season_Winners!A:B,2,FALSE), "")
A26: 2013-14 | B26: 3 | C26: SAB 31.08.2013 | D26: =RIGHT(C26,10) -> 31.08.2013 | E26: 0.95833333 | F26: CA Osasuna | G26: Villarreal CF | H26: 0-3 | I26: =IF(ISNUMBER(SEARCH("-",H26)),H26,"") -> 0-3 | J26: =IF(I26="","",LEFT(I26,FIND("-",I26)-1)) -> 0 | K26: =IF(I26="","",RIGHT(I26,LEN(I26)-FIND("-",I26))) -> 3 | L26: =IF(I26="","",IF(J26>K26,F26,IF(K26>J26,G26,"Draw"))) -> Villarreal CF | M26: =IF(COUNTIF($A$2:A26,A26)=1, VLOOKUP(A26,Season_Winners!A:B,2,FALSE), "")
A27: 2013-14 | B27: 3 | C27: DOM 01.09.2013 | D27: =RIGHT(C27,10) -> 01.09.2013 | E27: 0.5 | F27: Real Madrid | G27: Athletic Club | H27: 46025 | I27: =IF(ISNUMBER(SEARCH("-",H27)),H27,"") | J27: =IF(I27="","",LEFT(I27,FIND("-",I27)-1)) | K27: =IF(I27="","",RIGHT(I27,LEN(I27)-FIND("-",I27))) | L27: =IF(I27="","",IF(J27>K27,F27,IF(K27>J27,G27,"Draw"))) | M27: =IF(COUNTIF($A$2:A27,A27)=1, VLOOKUP(A27,Season_Winners!A:B,2,FALSE), "")
A28: 2013-14 | B28: 3 | C28: DOM 01.09.2013 | D28: =RIGHT(C28,10) -> 01.09.2013 | E28: 0.70833333 | F28: RCD Espanyol de Barcelona | G28: Real Betis | H28: 0-0 | I28: =IF(ISNUMBER(SEARCH("-",H28)),H28,"") -> 0-0 | J28: =IF(I28="","",LEFT(I28,FIND("-",I28)-1)) -> 0 | K28: =IF(I28="","",RIGHT(I28,LEN(I28)-FIND("-",I28))) -> 0 | L28: =IF(I28="","",IF(J28>K28,F28,IF(K28>J28,G28,"Draw"))) -> Draw | M28: =IF(COUNTIF($A$2:A28,A28)=1, VLOOKUP(A28,Season_Winners!A:B,2,FALSE), "")
A29: 2013-14 | B29: 3 | C29: DOM 01.09.2013 | D29: =RIGHT(C29,10) -> 01.09.2013 | E29: 0.79166667 | F29: Real Sociedad | G29: AtlÃ©tico de Madrid | H29: 46054 | I29: =IF(ISNUMBER(SEARCH("-",H29)),H29,"") | J29: =IF(I29="","",LEFT(I29,FIND("-",I29)-1)) | K29: =IF(I29="","",RIGHT(I29,LEN(I29)-FIND("-",I29))) | L29: =IF(I29="","",IF(J29>K29,F29,IF(K29>J29,G29,"Draw"))) | M29: =IF(COUNTIF($A$2:A29,A29)=1, VLOOKUP(A29,Season_Winners!A:B,2,FALSE), "")
A30: 2013-14 | B30: 3 | C30: DOM 01.09.2013 | D30: =RIGHT(C30,10) -> 01.09.2013 | E30: 0.875 | F30: Sevilla FC | G30: MÃ¡laga CF | H30: 46055 | I30: =IF(ISNUMBER(SEARCH("-",H30)),H30,"") | J30: =IF(I30="","",LEFT(I30,FIND("-",I30)-1)) | K30: =IF(I30="","",RIGHT(I30,LEN(I30)-FIND("-",I30))) | L30: =IF(I30="","",IF(J30>K30,F30,IF(K30>J30,G30,"Draw"))) | M30: =IF(COUNTIF($A$2:A30,A30)=1, VLOOKUP(A30,Season_Winners!A:B,2,FALSE), "")
A31: 2013-14 | B31: 3 | C31: DOM 01.09.2013 | D31: =RIGHT(C31,10) -> 01.09.2013 | E31: 0.875 | F31: Valencia CF | G31: FC Barcelona | H31: 46083 | I31: =IF(ISNUMBER(SEARCH("-",H31)),H31,"") | J31: =IF(I31="","",LEFT(I31,FIND("-",I31)-1)) | K31: =IF(I31="","",RIGHT(I31,LEN(I31)-FIND("-",I31))) | L31: =IF(I31="","",IF(J31>K31,F31,IF(K31>J31,G31,"Draw"))) | M31: =IF(COUNTIF($A$2:A31,A31)=1, VLOOKUP(A31,Season_Winners!A:B,2,FALSE), "")
A32: 2013-14 | B32: 4 | C32: SAB 14.09.2013 | D32: =RIGHT(C32,10) -> 14.09.2013 | E32: 0.66666667 | F32: AtlÃ©tico de Madrid | G32: UD AlmerÃ­a | H32: 46057 | I32: =IF(ISNUMBER(SEARCH("-",H32)),H32,"") | J32: =IF(I32="","",LEFT(I32,FIND("-",I32)-1)) | K32: =IF(I32="","",RIGHT(I32,LEN(I32)-FIND("-",I32))) | L32: =IF(I32="","",IF(J32>K32,F32,IF(K32>J32,G32,"Draw"))) | M32: =IF(COUNTIF($A$2:A32,A32)=1, VLOOKUP(A32,Season_Winners!A:B,2,FALSE), "")
A33: 2013-14 | B33: 4 | C33: SAB 14.09.2013 | D33: =RIGHT(C33,10) -> 14.09.2013 | E33: 0.75 | F33: Levante UD | G33: Real Sociedad | H33: 0-0 | I33: =IF(ISNUMBER(SEARCH("-",H33)),H33,"") -> 0-0 | J33: =IF(I33="","",LEFT(I33,FIND("-",I33)-1)) -> 0 | K33: =IF(I33="","",RIGHT(I33,LEN(I33)-FIND("-",I33))) -> 0 | L33: =IF(I33="","",IF(J33>K33,F33,IF(K33>J33,G33,"Draw"))) -> Draw | M33: =IF(COUNTIF($A$2:A33,A33)=1, VLOOKUP(A33,Season_Winners!A:B,2,FALSE), "")
A34: 2013-14 | B34: 4 | C34: SAB 14.09.2013 | D34: =RIGHT(C34,10) -> 14.09.2013 | E34: 0.83333333 | F34: FC Barcelona | G34: Sevilla FC | H34: 46056 | I34: =IF(ISNUMBER(SEARCH("-",H34)),H34,"") | J34: =IF(I34="","",LEFT(I34,FIND("-",I34)-1)) | K34: =IF(I34="","",RIGHT(I34,LEN(I34)-FIND("-",I34))) | L34: =IF(I34="","",IF(J34>K34,F34,IF(K34>J34,G34,"Draw"))) | M34: =IF(COUNTIF($A$2:A34,A34)=1, VLOOKUP(A34,Season_Winners!A:B,2,FALSE), "")
A35: 2013-14 | B35: 4 | C35: SAB 14.09.2013 | D35: =RIGHT(C35,10) -> 14.09.2013 | E35: 0.91666667 | F35: Villarreal CF | G35: Real Madrid | H35: 46055 | I35: =IF(ISNUMBER(SEARCH("-",H35)),H35,"") | J35: =IF(I35="","",LEFT(I35,FIND("-",I35)-1)) | K35: =IF(I35="","",RIGHT(I35,LEN(I35)-FIND("-",I35))) | L35: =IF(I35="","",IF(J35>K35,F35,IF(K35>J35,G35,"Draw"))) | M35: =IF(COUNTIF($A$2:A35,A35)=1, VLOOKUP(A35,Season_Winners!A:B,2,FALSE), "")
A36: 2013-14 | B36: 4 | C36: DOM 15.09.2013 | D36: =RIGHT(C36,10) -> 15.09.2013 | E36: 0.5 | F36: Granada CF | G36: RCD Espanyol de Barcelona | H36: 0-1 | I36: =IF(ISNUMBER(SEARCH("-",H36)),H36,"") -> 0-1 | J36: =IF(I36="","",LEFT(I36,FIND("-",I36)-1)) -> 0 | K36: =IF(I36="","",RIGHT(I36,LEN(I36)-FIND("-",I36))) -> 1 | L36: =IF(I36="","",IF(J36>K36,F36,IF(K36>J36,G36,"Draw"))) -> RCD Espanyol de Barcelona | M36: =IF(COUNTIF($A$2:A36,A36)=1, VLOOKUP(A36,Season_Winners!A:B,2,FALSE), "")
A37: 2013-14 | B37: 4 | C37: DOM 15.09.2013 | D37: =RIGHT(C37,10) -> 15.09.2013 | E37: 0.70833333 | F37: Getafe CF | G37: CA Osasuna | H37: 46024 | I37: =IF(ISNUMBER(SEARCH("-",H37)),H37,"") | J37: =IF(I37="","",LEFT(I37,FIND("-",I37)-1)) | K37: =IF(I37="","",RIGHT(I37,LEN(I37)-FIND("-",I37))) | L37: =IF(I37="","",IF(J37>K37,F37,IF(K37>J37,G37,"Draw"))) | M37: =IF(COUNTIF($A$2:A37,A37)=1, VLOOKUP(A37,Season_Winners!A:B,2,FALSE), "")
A38: 2013-14 | B38: 4 | C38: DOM 15.09.2013 | D38: =RIGHT(C38,10) -> 15.09.2013 | E38: 0.79166667 | F38: MÃ¡laga CF | G38: Rayo Vallecano | H38: 5-0 | I38: =IF(ISNUMBER(SEARCH("-",H38)),H38,"") -> 5-0 | J38: =IF(I38="","",LEFT(I38,FIND("-",I38)-1)) -> 5 | K38: =IF(I38="","",RIGHT(I38,LEN(I38)-FIND("-",I38))) -> 0 | L38: =IF(I38="","",IF(J38>K38,F38,IF(K38>J38,G38,"Draw"))) -> MÃ¡laga CF | M38: =IF(COUNTIF($A$2:A38,A38)=1, VLOOKUP(A38,Season_Winners!A:B,2,FALSE), "")
A39: 2013-14 | B39: 4 | C39: DOM 15.09.2013 | D39: =RIGHT(C39,10) -> 15.09.2013 | E39: 0.875 | F39: Real Betis | G39: Valencia CF | H39: 46025 | I39: =IF(ISNUMBER(SEARCH("-",H39)),H39,"") | J39: =IF(I39="","",LEFT(I39,FIND("-",I39)-1)) | K39: =IF(I39="","",RIGHT(I39,LEN(I39)-FIND("-",I39))) | L39: =IF(I39="","",IF(J39>K39,F39,IF(K39>J39,G39,"Draw"))) | M39: =IF(COUNTIF($A$2:A39,A39)=1, VLOOKUP(A39,Season_Winners!A:B,2,FALSE), "")
A40: 2013-14 | B40: 4 | C40: LUN 16.09.2013 | D40: =RIGHT(C40,10) -> 16.09.2013 | E40: 0.83333333 | F40: Elche CF | G40: Real Valladolid CF | H40: 0-0 | I40: =IF(ISNUMBER(SEARCH("-",H40)),H40,"") -> 0-0 | J40: =IF(I40="","",LEFT(I40,FIND("-",I40)-1)) -> 0 | K40: =IF(I40="","",RIGHT(I40,LEN(I40)-FIND("-",I40))) -> 0 | L40: =IF(I40="","",IF(J40>K40,F40,IF(K40>J40,G40,"Draw"))) -> Draw | M40: =IF(COUNTIF($A$2:A40,A40)=1, VLOOKUP(A40,Season_Winners!A:B,2,FALSE), "")
...

Sheet Season_Winners
A1: Season | B1: League winner
A2: 2013-14 | B2: Atlético de Madrid
A3: 2014-15 | B3: FC Barcelona
A4: 2015-16 | B4: FC Barcelona
A5: 2016-17 | B5: Real Madrid
A6: 2017-18 | B6: FC Barcelona
A7: 2018-19 | B7: FC Barcelona
A8: 2019-20 | B8: Real Madrid
A9: 2020-21 | B9: Atlético de Madrid
A10: 2021-22 | B10: Real Madrid
A11: 2022-23 | B11: FC Barcelona
